Workbook
Name SegmentaciónDeDatos_species: #N/A

Sheet penguins_size
A1: species | B1: island | C1: longitud pico (mm) | D1: profundidad pico (mm) | E1: longitud aleta (mm) | F1: body_mass_g | G1: sex | H1: Intervalos | I1: Dimension
A2: Gentoo | B2: Biscoe | C2: 46.1 | D2: 13.2 | E2: 211 | F2: 4500 | G2: FEMALE | H2: (210-215] | I2: Pequeño
A3: Gentoo | B3: Biscoe | C3: 50 | D3: 16.3 | E3: 230 | F3: 5700 | G3: MALE | H3: (230-235] | I3: Grande
A4: Gentoo | B4: Biscoe | C4: 48.7 | D4: 14.1 | E4: 210 | F4: 4450 | G4: FEMALE | H4: (210-215] | I4: Pequeño
A5: Gentoo | B5: Biscoe | C5: 50 | D5: 15.2 | E5: 218 | F5: 5700 | G5: MALE | H5: (215-220] | I5: Grande
A6: Gentoo | B6: Biscoe | C6: 47.6 | D6: 14.5 | E6: 215 | F6: 5400 | G6: MALE | H6: (215-220] | I6: Grande
A7: Gentoo | B7: Biscoe | C7: 46.5 | D7: 13.5 | E7: 210 | F7: 4550 | G7: FEMALE | H7: (210-215] | I7: Pequeño
A8: Gentoo | B8: Biscoe | C8: 45.4 | D8: 14.6 | E8: 211 | F8: 4800 | G8: FEMALE | H8: (210-215] | I8: Pequeño
A9: Gentoo | B9: Biscoe | C9: 46.7 | D9: 15.3 | E9: 219 | F9: 5200 | G9: MALE | H9: (215-220] | I9: Grande
A10: Gentoo | B10: Biscoe | C10: 43.3 | D10: 13.4 | E10: 209 | F10: 4400 | G10: FEMALE | H10: (205-210] | I10: Pequeño
A11: Gentoo | B11: Biscoe | C11: 46.8 | D11: 15.4 | E11: 215 | F11: 5150 | G11: MALE | H11: (215-220] | I11: Grande
A12: Gentoo | B12: Biscoe | C12: 40.9 | D12: 13.7 | E12: 214 | F12: 4650 | G12: FEMALE | H12: (210-215] | I12: Pequeño
A13: Gentoo | B13: Biscoe | C13: 49 | D13: 16.1 | E13: 216 | F13: 5550 | G13: MALE | H13: (215-220] | I13: Grande
... A158: Adelie | B158: Biscoe | C158: 39.7 | D158: 18.9 | E158: 184 | F158: 3550 | G158: MALE | H158: (180-185] | I158: Pequeño
A159: Adelie | B159: Biscoe | C159: 38.6 | D159: 17.2 | E159: 199 | F159: 3750 | G159: FEMALE | H159: (195-200] | I159: Pequeño | L159: =MIN(E2:E168) -> 172
A160: Adelie | B160: Biscoe | C160: 38.2 | D160: 20 | E160: 190 | F160: 3900 | G160: MALE | H160: (190-195] | I160: Pequeño | L160: =MAX(E2:E168) -> 231
A161: Adelie | B161: Biscoe | C161: 38.1 | D161: 17 | E161: 181 | F161: 3175 | G161: FEMALE | H161: (180-185] | I161: Pequeño
A162: Adelie | B162: Biscoe | C162: 43.2 | D162: 19 | E162: 197 | F162: 4775 | G162: MALE | H162: (195-200] | I162: Pequeño
A163: Adelie | B163: Biscoe | C163: 38.1 | D163: 16.5 | E163: 198 | F163: 3825 | G163: FEMALE | H163: (195-200] | I163: Pequeño
A164: Adelie | B164: Biscoe | C164: 45.6 | D164: 20.3 | E164: 191 | F164: 4600 | G164: MALE | H164: (190-195] | I164: Pequeño
A165: Adelie | B165: Biscoe | C165: 39.7 | D165: 17.7 | E165: 193 | F165: 3200 | G165: FEMALE | H165: (190-195] | I165: Pequeño
A166: Adelie | B166: Biscoe | C166: 42.2 | D166: 19.5 | E166: 197 | F166: 4275 | G166: MALE | H166: (195-200] | I166: Pequeño
A167: Adelie | B167: Biscoe | C167: 39.6 | D167: 20.7 | E167: 191 | F167: 3900 | G167: FEMALE | H167: (190-195] | I167: Pequeño
A168: Adelie | B168: Biscoe | C168: 42.7 | D168: 18.3 | E168: 196 | F168: 4075 | G168: MALE | H168: (195-200] | I168: Pequeño
A169: Adelie | B169: Dream | C169: 39.5 | D169: 16.7 | E169: 178 | F169: 3250 | G169: FEMALE | H169: (175-180] | I169: Pequeño
A170: Adelie | B170: Dream | C170: 37.2 | D170: 18.1 | E170: 178 | F170: 3900 | G170: MALE | H170: (175-180] | I170: Pequeño
A171: Adelie | B171: Dream | C171: 39.5 | D171: 17.8 | E171: 188 | F171: 3300 | G171: FEMALE | H171: (185-190] | I171: Pequeño
A172: Adelie | B172: Dream | C172: 40.9 | D172: 18.9 | E172: 184 | F172: 3900 | G172: MALE | H172: (180-185] | I172: Pequeño
... A343: Adelie | B343: Torgersen | C343: 43.1 | D343: 19.2 | E343: 197 | F343: 3500 | G343: MALE | H343: (195-200] | I343: Pequeño

Sheet Islas
A1: island
A2: Torgersen
A3: Biscoe
A4: Dream

Sheet Sexo
A1: sex
A2: MALE
A3: FEMALE

Sheet Especies
A1: species
A2: Adelie
A3: Chinstrap
A4: Gentoo

Sheet Hoja1
B1: (170-175] | C1: (175-180] | D1: (180-185] | E1: (185-190] | F1: (190-195] | G1: (195-200] | H1: (200-205] | I1: (205-210] | J1: (210-215] | K1: (215-220] | L1: (220-225] | M1: (225-231]
A2: Longitud de la aleta | B2: =COUNTIFS(penguins_size!$E$2:$E$343,">170",penguins_size!$E$2:$E$343,"<=175") -> 2 | C2: =COUNTIFS(penguins_size!$E$2:$E$343,">175",penguins_size!$E$2:$E$343,"<=180") -> 11 | D2: =COUNTIFS(penguins_size!$E$2:$E$343,">180",penguins_size!$E$2:$E$343,"<=185") -> 28 | E2: =COUNTIFS(penguins_size!$E$2:$E$343,">185",penguins_size!$E$2:$E$343,"<=190") -> 58 | F2: =COUNTIFS(penguins_size!$E$2:$E$343,">190",penguins_size!$E$2:$E$343,"<=195") -> 57 | G2: =COUNTIFS(penguins_size!$E$2:$E$343,">195",penguins_size!$E$2:$E$343,"<=200") -> 38 | H2: =COUNTIFS(penguins_size!$E$2:$E$343,">200",penguins_size!$E$2:$E$343,"<=205") -> 18 | I2: =COUNTIFS(penguins_size!$E$2:$E$343,">205",penguins_size!$E$2:$E$343,"<=210") -> 30 | J2: =COUNTIFS(penguins_size!$E$2:$E$343,">210",penguins_size!$E$2:$E$343,"<=215") -> 33 | K2: =COUNTIFS(penguins_size!$E$2:$E$343,">215",penguins_size!$E$2:$E$343,"<=220") -> 32 | L2: =COUNTIFS(penguins_size!$E$2:$E$343,">220",penguins_size!$E$2:$E$343,"<=225") -> 20 | M2: =COUNTIFS(penguins_size!$E$2:$E$343,">225",penguins_size!$E$2:$E$343,"<=231") -> 15
B5: (170-175] | C5: (175-180] | D5: (180-185] | E5: (185-190] | F5: (190-195] | G5: (195-200] | H5: (200-205] | I5: (205-210] | J5: (210-215] | K5: (215-220] | L5: (220-225] | M5: (225-231]
A6: Longitud de la aleta | B6: =COUNTIFS(penguins_size!$E$2:$E$343,">170",penguins_size!$E$2:$E$343,"<=175",penguins_size!$G$2:$G$343,"FEMALE") -> 2 | C6: =COUNTIFS(penguins_size!$E$2:$E$343,">175",penguins_size!$E$2:$E$343,"<=180",penguins_size!$G$2:$G$343,"FEMALE") -> 7 | D6: =COUNTIFS(penguins_size!$E$2:$E$343,">180",penguins_size!$E$2:$E$343,"<=185",penguins_size!$G$2:$G$343,"FEMALE") -> 19 | E6: =COUNTIFS(penguins_size!$E$2:$E$343,">185",penguins_size!$E$2:$E$343,"<=190",penguins_size!$G$2:$G$343,"FEMALE") -> 41 | F6: =COUNTIFS(penguins_size!$E$2:$E$343,">190",penguins_size!$E$2:$E$343,"<=195",penguins_size!$G$2:$G$343,"FEMALE") -> 30 | G6: =COUNTIFS(penguins_size!$E$2:$E$343,">195",penguins_size!$E$2:$E$343,"<=200",penguins_size!$G$2:$G$343,"FEMALE") -> 11 | H6: =COUNTIFS(penguins_size!$E$2:$E$343,">200",penguins_size!$E$2:$E$343,"<=205",penguins_size!$G$2:$G$343,"FEMALE") -> 3 | I6: =COUNTIFS(penguins_size!$E$2:$E$343,">205",penguins_size!$E$2:$E$343,"<=210",penguins_size!$G$2:$G$343,"FEMALE") -> 21 | J6: =COUNTIFS(penguins_size!$E$2:$E$343,">210",penguins_size!$E$2:$E$343,"<=215",penguins_size!$G$2:$G$343,"FEMALE") -> 23 | K6: =COUNTIFS(penguins_size!$E$2:$E$343,">215",penguins_size!$E$2:$E$343,"<=220",penguins_size!$G$2:$G$343,"FEMALE") -> 15 | L6: =COUNTIFS(penguins_size!$E$2:$E$343,">220",penguins_size!$E$2:$E$343,"<=225",penguins_size!$G$2:$G$343,"FEMALE") -> 1 | M6: =COUNTIFS(penguins_size!$E$2:$E$343,">225",penguins_size!$E$2:$E$343,"<=231",penguins_size!$G$2:$G$343,"FEMALE") -> 0
A30: Longitud de la aleta | B30: (170-175] | C30: (175-180] | D30: (180-185] | E30: (185-190] | F30: (190-195] | G30: (195-200] | H30: (200-205] | I30: (205-210] | J30: (210-215] | K30: (215-220] | L30: (220-225] | M30: (225-231]
A31: Gentoo | B31: =COUNTIFS(penguins_size!$E$2:$E$343,">170",penguins_size!$E$2:$E$343,"<=175",penguins_size!$A$2:$A$343,"Gentoo") -> 0 | C31: =COUNTIFS(penguins_size!$E$2:$E$343,">175",penguins_size!$E$2:$E$343,"<=180",penguins_size!$A$2:$A$343,"Gentoo") -> 0 | D31: =COUNTIFS(penguins_size!$E$2:$E$343,">180",penguins_size!$E$2:$E$343,"<=185",penguins_size!$A$2:$A$343,"Gentoo") -> 0 | E31: =COUNTIFS(penguins_size!$E$2:$E$343,">185",penguins_size!$E$2:$E$343,"<=190",penguins_size!$A$2:$A$343,"Gentoo") -> 0 | F31: =COUNTIFS(penguins_size!$E$2:$E$343,">190",penguins_size!$E$2:$E$343,"<=195",penguins_size!$A$2:$A$343,"Gentoo") -> 0 | G31: =COUNTIFS(penguins_size!$E$2:$E$343,">195",penguins_size!$E$2:$E$343,"<=200",penguins_size!$A$2:$A$343,"Gentoo") -> 0 | H31: =COUNTIFS(penguins_size!$E$2:$E$343,">200",penguins_size!$E$2:$E$343,"<=205",penguins_size!$A$2:$A$343,"Gentoo") -> 1 | I31: =COUNTIFS(penguins_size!$E$2:$E$343,">205",penguins_size!$E$2:$E$343,"<=210",penguins_size!$A$2:$A$343,"Gentoo") -> 23 | J31: =COUNTIFS(penguins_size!$E$2:$E$343,">210",penguins_size!$E$2:$E$343,"<=215",penguins_size!$A$2:$A$343,"Gentoo") -> 32 | K31: =COUNTIFS(penguins_size!$E$2:$E$343,">215",penguins_size!$E$2:$E$343,"<=220",penguins_size!$A$2:$A$343,"Gentoo") -> 32 | L31: =COUNTIFS(penguins_size!$E$2:$E$343,">220",penguins_size!$E$2:$E$343,"<=225",penguins_size!$A$2:$A$343,"Gentoo") -> 20 | M31: =COUNTIFS(penguins_size!$E$2:$E$343,">225",penguins_size!$E$2:$E$343,"<=231",penguins_size!$A$2:$A$343,"Gentoo") -> 15
A32: Chinstrap | B32: =COUNTIFS(penguins_size!$E$2:$E$343,">170",penguins_size!$E$2:$E$343,"<=175",penguins_size!$A$2:$A$343,"Chinstrap") -> 0 | C32: =COUNTIFS(penguins_size!$E$2:$E$343,">175",penguins_size!$E$2:$E$343,"<=180",penguins_size!$A$2:$A$343,"Chinstrap") -> 1 | D32: =COUNTIFS(penguins_size!$E$2:$E$343,">180",penguins_size!$E$2:$E$343,"<=185",penguins_size!$A$2:$A$343,"Chinstrap") -> 3 | E32: =COUNTIFS(penguins_size!$E$2:$E$343,">185",penguins_size!$E$2:$E$343,"<=190",penguins_size!$A$2:$A$343,"Chinstrap") -> 11 | F32: =COUNTIFS(penguins_size!$E$2:$E$343,">190",penguins_size!$E$2:$E$343,"<=195",penguins_size!$A$2:$A$343,"Chinstrap") -> 18 | G32: =COUNTIFS(penguins_size!$E$2:$E$343,">195",penguins_size!$E$2:$E$343,"<=200",penguins_size!$A$2:$A$343,"Chinstrap") -> 17 | H32: =COUNTIFS(penguins_size!$E$2:$E$343,">200",penguins_size!$E$2:$E$343,"<=205",penguins_size!$A$2:$A$343,"Chinstrap") -> 12 | I32: =COUNTIFS(penguins_size!$E$2:$E$343,">205",penguins_size!$E$2:$E$343,"<=210",penguins_size!$A$2:$A$343,"Chinstrap") -> 5 | J32: =COUNTIFS(penguins_size!$E$2:$E$343,">210",penguins_size!$E$2:$E$343,"<=215",penguins_size!$A$2:$A$343,"Chinstrap") -> 1 | K32: =COUNTIFS(penguins_size!$E$2:$E$343,">215",penguins_size!$E$2:$E$343,"<=220",penguins_size!$A$2:$A$343,"Chinstrap") -> 0 | L32: =COUNTIFS(penguins_size!$E$2:$E$343,">220",penguins_size!$E$2:$E$343,"<=225",penguins_size!$A$2:$A$343,"Chinstrap") -> 0 | M32: =COUNTIFS(penguins_size!$E$2:$E$343,">225",penguins_size!$E$2:$E$343,"<=231",penguins_size!$A$2:$A$343,"Chinstrap") -> 0
A33: Adelie | B33: =COUNTIFS(penguins_size!$E$2:$E$343,">170",penguins_size!$E$2:$E$343,"<=175",penguins_size!$A$2:$A$343,"Adelie") -> 2 | C33: =COUNTIFS(penguins_size!$E$2:$E$343,">175",penguins_size!$E$2:$E$343,"<=180",penguins_size!$A$2:$A$343,"Adelie") -> 10 | D33: =COUNTIFS(penguins_size!$E$2:$E$343,">180",penguins_size!$E$2:$E$343,"<=185",penguins_size!$A$2:$A$343,"Adelie") -> 25 | E33: =COUNTIFS(penguins_size!$E$2:$E$343,">185",penguins_size!$E$2:$E$343,"<=190",penguins_size!$A$2:$A$343,"Adelie") -> 47 | F33: =COUNTIFS(penguins_size!$E$2:$E$343,">190",penguins_size!$E$2:$E$343,"<=195",penguins_size!$A$2:$A$343,"Adelie") -> 39 | G33: =COUNTIFS(penguins_size!$E$2:$E$343,">195",penguins_size!$E$2:$E$343,"<=200",penguins_size!$A$2:$A$343,"Adelie") -> 21 | H33: =COUNTIFS(penguins_size!$E$2:$E$343,">200",penguins_size!$E$2:$E$343,"<=205",penguins_size!$A$2:$A$343,"Adelie") -> 5 | I33: =COUNTIFS(penguins_size!$E$2:$E$343,">205",penguins_size!$E$2:$E$343,"<=210",penguins_size!$A$2:$A$343,"Adelie") -> 2 | J33: =COUNTIFS(penguins_size!$E$2:$E$343,">210",penguins_size!$E$2:$E$343,"<=215",penguins_size!$A$2:$A$343,"Adelie") -> 0 | K33: =COUNTIFS(penguins_size!$E$2:$E$343,">215",penguins_size!$E$2:$E$343,"<=220",penguins_size!$A$2:$A$343,"Adelie") -> 0 | L33: =COUNTIFS(penguins_size!$E$2:$E$343,">220",penguins_size!$E$2:$E$343,"<=225",penguins_size!$A$2:$A$343,"Adelie") -> 0 | M33: =COUNTIFS(penguins_size!$E$2:$E$343,">225",penguins_size!$E$2:$E$343,"<=231",penguins_size!$A$2:$A$343,"Adelie") -> 0

Sheet Tablas dinámicas
B3: Etiquetas de columna | I3: Etiquetas de columna | O3: Etiquetas de columna
A4: Valores | B4: FEMALE | C4: MALE | D4: Total general | H4: Valores | I4: Adelie | J4: Chinstrap | K4: Gentoo | L4: Total general | O4: Adelie | P4: Chinstrap | Q4: Gentoo | R4: Total general
A5: Longitud Pico Media | B5: 42.041618 | C5: 45.846746 | D5: 43.92193 | H5: Longitud Pico Media | I5: 38.791391 | J5: 48.833824 | K5: 47.504878 | L5: 43.92193 | N5: Peso medio | O5: 3700.6623 | P5: 3733.0882 | Q5: 5076.0163 | R5: 4201.7544
A6: Profundidad Pico Media | B6: 16.44104 | C6: 17.878107 | D6: 17.15117 | H6: Profundidad Pico Media | I6: 18.346358 | J6: 18.420588 | K6: 14.982114 | L6: 17.15117
A7: Aleta Media | B7: 197.33526 | C7: 204.57988 | D7: 200.9152 | H7: Aleta Media | I7: 189.95364 | J7: 195.82353 | K7: 217.18699 | L7: 200.9152
B10: Etiquetas de columna
B11: FEMALE | C11: MALE | D11: Total general
A12: Peso medio | B12: 3863.8728 | C12: 4547.6331 | D12: 4201.7544 | H12: Peso medio | I12: Etiquetas de columna
H13: Etiquetas de fila | I13: Adelie | J13: Chinstrap | K13: Gentoo | L13: Total general
H14: FEMALE | I14: 3379.8077 | J14: 3527.2059 | K14: 4670.4918 | L14: 3863.8728
H15: MALE | I15: 4043.4932 | J15: 3938.9706 | K15: 5475 | L15: 4547.6331
H16: Total general | I16: 3700.6623 | J16: 3733.0882 | K16: 5076.0163 | L16: 4201.7544
A25: Etiquetas de fila | B25: Recuento de species
A26: Adelie
A27: (170-175] | B27: 2
A28: (175-180] | B28: 5
A29: (180-185] | B29: 22
A30: (185-190] | B30: 36
A31: (190-195] | B31: 47
A32: (195-200] | B32: 30
A33: (200-205] | B33: 6
A34: (205-210] | B34: 2
A35: (210-215] | B35: 1
A36: Chinstrap
A37: (175-180] | B37: 1
A38: (180-185] | B38: 2
A39: (185-190] | B39: 9
A40: (190-195] | B40: 15
A41: (195-200] | B41: 21
A42: (200-205] | B42: 12
A43: (205-210] | B43: 4
A44: (210-215] | B44: 4
A45: Gentoo
A46: (200-205] | B46: 1
A47: (205-210] | B47: 13
A48: (210-215] | B48: 30
A49: (215-220] | B49: 36
A50: (220-225] | B50: 24
A51: (225-231] | B51: 11
A52: (230-235] | B52: 8
...

Sheet Gráficas

Sheet Dashboard
